Workbook

Sheet Main Data
A1: Area_Name | B1: LGA | C1: GPS LOCATION (LATITUDE) | D1: GPS LOCATION (LONGITUDE) | E1: Annual_Rent_Min (₦) | F1: Annual_Rent_Max (₦) | G1: Annual_Rent_Avg (₦) | H1: Network_Coverage (GLO) (4g) | I1: Network_Coverage (AIRTEL) (4g) | J1: Network_Coverage (MTN) (4g) | K1: Overall_Safety (1-5) | L1: Overall_Road_Condition (1-5) | M1: Power_Supply_Hours (expected) | N1: Transport_Availability (most common) | O1: Cost of Market items | P1: Access to hospitals (healthcare) (1-5) | Q1: Quality of Hospitals(health care) | R1: Access to recreational activities (1-5) | S1: Availability of supermarket and stores (1-5) | T1: Cost of supermarket and stores
A2: Kubwa | B2: Bwari Area Council (BAC) | C2: 9.1547596 | D2: 7.3245684 | E2: 800000 | F2: 6500000 | G2: 1500000 | H2: slow | I2: fair | J2: Strong | K2: =_xlfn.XLOOKUP('Main Data'!A2,'PIVOT TABLES'!$A$4:$A$24,'PIVOT TABLES'!$B$4:$B$24,"N/A") -> 3.8333333 | L2: =_xlfn.XLOOKUP(A2,'PIVOT TABLES'!$D$4:$D$24,'PIVOT TABLES'!$E$4:$E$24,"n/a") -> 3 | M2: 12-16 | N2: keke, Taxi, Bus, Bike | O2: Moderate | P2: =_xlfn.XLOOKUP(A2,'PIVOT TABLES'!$G$4:$G$24,'PIVOT TABLES'!$H$4:$H$24,"N/A") -> 3.5 | Q2: Fair | R2: =_xlfn.XLOOKUP(A2,'PIVOT TABLES'!$A$27:$A$47,'PIVOT TABLES'!$B$27:$B$47,"N/A") -> 1.8333333 | S2: =_xlfn.XLOOKUP(A2,'PIVOT TABLES'!$D$27:$D$47,'PIVOT TABLES'!$E$27:$E$47,"N/A") -> 3.8333333 | T2: Fair/Expensive
A3: Lugbe | B3: Abuja Municipal Area Council (AMAC) | C3: 8.9638251 | D3: 7.3813378 | E3: 800000 | F3: 5000000 | G3: 1500000 | H3: slow | I3: fair | J3: Strong | K3: =_xlfn.XLOOKUP('Main Data'!A3,'PIVOT TABLES'!$A$4:$A$24,'PIVOT TABLES'!$B$4:$B$24,"N/A") -> 3.25 | L3: =_xlfn.XLOOKUP(A3,'PIVOT TABLES'!$D$4:$D$24,'PIVOT TABLES'!$E$4:$E$24,"n/a") -> 2.5 | M3: 12-16 | N3: Taxi, Bike, keke | O3: Moderate | P3: =_xlfn.XLOOKUP(A3,'PIVOT TABLES'!$G$4:$G$24,'PIVOT TABLES'!$H$4:$H$24,"N/A") -> 3.25 | Q3: Fair | R3: =_xlfn.XLOOKUP(A3,'PIVOT TABLES'!$A$27:$A$47,'PIVOT TABLES'!$B$27:$B$47,"N/A") -> 1.5 | S3: =_xlfn.XLOOKUP(A3,'PIVOT TABLES'!$D$27:$D$47,'PIVOT TABLES'!$E$27:$E$47,"N/A") -> 3.25 | T3: Fair
A4: Kado | B4: Abuja Municipal Area Council (AMAC) | C4: 9.0888363 | D4: 7.42607 | E4: 3000000 | F4: 20000000 | G4: 3500000 | H4: fair | I4: fair | J4: Strong | K4: =_xlfn.XLOOKUP('Main Data'!A4,'PIVOT TABLES'!$A$4:$A$24,'PIVOT TABLES'!$B$4:$B$24,"N/A") -> 4.5 | L4: =_xlfn.XLOOKUP(A4,'PIVOT TABLES'!$D$4:$D$24,'PIVOT TABLES'!$E$4:$E$24,"n/a") -> 5 | M4: 16-18 | N4: keke, Taxi | O4: Expensive | P4: =_xlfn.XLOOKUP(A4,'PIVOT TABLES'!$G$4:$G$24,'PIVOT TABLES'!$H$4:$H$24,"N/A") -> 3.5 | Q4: Excellent | R4: =_xlfn.XLOOKUP(A4,'PIVOT TABLES'!$A$27:$A$47,'PIVOT TABLES'!$B$27:$B$47,"N/A") -> 3 | S4: =_xlfn.XLOOKUP(A4,'PIVOT TABLES'!$D$27:$D$47,'PIVOT TABLES'!$E$27:$E$47,"N/A") -> 4 | T4: Expensive
A5: Durumi | B5: Abuja Municipal Area Council (AMAC) | C5: 9.0198629 | D5: 7.4659708 | E5: 2200000 | F5: 6000000 | G5: 2500000 | H5: fair | I5: strong | J5: Strong | K5: =_xlfn.XLOOKUP('Main Data'!A5,'PIVOT TABLES'!$A$4:$A$24,'PIVOT TABLES'!$B$4:$B$24,"N/A") -> 3 | L5: =_xlfn.XLOOKUP(A5,'PIVOT TABLES'!$D$4:$D$24,'PIVOT TABLES'!$E$4:$E$24,"n/a") -> 1 | M5: 18-20 | N5: keke, Taxi, Bike | O5: Moderate | P5: =_xlfn.XLOOKUP(A5,'PIVOT TABLES'!$G$4:$G$24,'PIVOT TABLES'!$H$4:$H$24,"N/A") -> 3 | Q5: Poor | R5: =_xlfn.XLOOKUP(A5,'PIVOT TABLES'!$A$27:$A$47,'PIVOT TABLES'!$B$27:$B$47,"N/A") -> 2 | S5: =_xlfn.XLOOKUP(A5,'PIVOT TABLES'!$D$27:$D$47,'PIVOT TABLES'!$E$27:$E$47,"N/A") -> 4 | T5: Fair
A6: Garki | B6: Abuja Municipal Area Council (AMAC) | C6: 9.0317907 | D6: 7.4824469 | E6: 2000000 | F6: 5500000 | G6: 2500000 | H6: fair | I6: strong | J6: Strong | K6: =_xlfn.XLOOKUP('Main Data'!A6,'PIVOT TABLES'!$A$4:$A$24,'PIVOT TABLES'!$B$4:$B$24,"N/A") -> 4 | L6: =_xlfn.XLOOKUP(A6,'PIVOT TABLES'!$D$4:$D$24,'PIVOT TABLES'!$E$4:$E$24,"n/a") -> 4 | M6: 18-20 | N6: Taxi | O6: Expensive | P6: =_xlfn.XLOOKUP(A6,'PIVOT TABLES'!$G$4:$G$24,'PIVOT TABLES'!$H$4:$H$24,"N/A") -> 5 | Q6: Fair | R6: =_xlfn.XLOOKUP(A6,'PIVOT TABLES'!$A$27:$A$47,'PIVOT TABLES'!$B$27:$B$47,"N/A") -> 4 | S6: =_xlfn.XLOOKUP(A6,'PIVOT TABLES'!$D$27:$D$47,'PIVOT TABLES'!$E$27:$E$47,"N/A") -> 5 | T6: Fair
A7: Maitama | B7: Abuja Municipal Area Council (AMAC) | C7: 9.1091921 | D7: 7.4959102 | E7: 5000000 | F7: 140000000 | G7: 5000000 | H7: fair | I7: strong | J7: Strong | K7: =_xlfn.XLOOKUP('Main Data'!A7,'PIVOT TABLES'!$A$4:$A$24,'PIVOT TABLES'!$B$4:$B$24,"N/A") -> 4 | L7: =_xlfn.XLOOKUP(A7,'PIVOT TABLES'!$D$4:$D$24,'PIVOT TABLES'!$E$4:$E$24,"n/a") -> 4 | M7: 20-24 | N7: Taxi | O7: Cheap | P7: =_xlfn.XLOOKUP(A7,'PIVOT TABLES'!$G$4:$G$24,'PIVOT TABLES'!$H$4:$H$24,"N/A") -> 2 | Q7: Fair | R7: =_xlfn.XLOOKUP(A7,'PIVOT TABLES'!$A$27:$A$47,'PIVOT TABLES'!$B$27:$B$47,"N/A") -> 4 | S7: =_xlfn.XLOOKUP(A7,'PIVOT TABLES'!$D$27:$D$47,'PIVOT TABLES'!$E$27:$E$47,"N/A") -> 4 | T7: Fair
A8: Wuse | B8: Abuja Municipal Area Council (AMAC) | C8: 9.0754166 | D8: 7.4774255 | E8: 2000000 | F8: 70000000 | G8: 2000000 | H8: fair | I8: strong | J8: Strong | K8: =_xlfn.XLOOKUP('Main Data'!A8,'PIVOT TABLES'!$A$4:$A$24,'PIVOT TABLES'!$B$4:$B$24,"N/A") -> 4 | L8: =_xlfn.XLOOKUP(A8,'PIVOT TABLES'!$D$4:$D$24,'PIVOT TABLES'!$E$4:$E$24,"n/a") -> 4.3333333 | M8: 20-24 | N8: Taxi, keke | O8: Moderate | P8: =_xlfn.XLOOKUP(A8,'PIVOT TABLES'!$G$4:$G$24,'PIVOT TABLES'!$H$4:$H$24,"N/A") -> 3.6666667 | Q8: Excellent | R8: =_xlfn.XLOOKUP(A8,'PIVOT TABLES'!$A$27:$A$47,'PIVOT TABLES'!$B$27:$B$47,"N/A") -> 4.3333333 | S8: =_xlfn.XLOOKUP(A8,'PIVOT TABLES'!$D$27:$D$47,'PIVOT TABLES'!$E$27:$E$47,"N/A") -> 4.6666667 | T8: Fair/Expensive
A9: Jabi | B9: Abuja Municipal Area Council (AMAC) | C9: 9.0392418 | D9: 7.4152325 | E9: 2000000 | F9: 80000000 | G9: 25000000 | H9: fair | I9: strong | J9: Strong | K9: =_xlfn.XLOOKUP('Main Data'!A9,'PIVOT TABLES'!$A$4:$A$24,'PIVOT TABLES'!$B$4:$B$24,"N/A") -> 5 | L9: =_xlfn.XLOOKUP(A9,'PIVOT TABLES'!$D$4:$D$24,'PIVOT TABLES'!$E$4:$E$24,"n/a") -> 5 | M9: 18-20 | N9: keke, Taxi | O9: Expensive | P9: =_xlfn.XLOOKUP(A9,'PIVOT TABLES'!$G$4:$G$24,'PIVOT TABLES'!$H$4:$H$24,"N/A") -> 2 | Q9: Excellent | R9: =_xlfn.XLOOKUP(A9,'PIVOT TABLES'!$A$27:$A$47,'PIVOT TABLES'!$B$27:$B$47,"N/A") -> 4.5 | S9: =_xlfn.XLOOKUP(A9,'PIVOT TABLES'!$D$27:$D$47,'PIVOT TABLES'!$E$27:$E$47,"N/A") -> 3 | T9: Moderate
A10: Utako | B10: Abuja Municipal Area Council (AMAC) | C10: 9.0677037 | D10: 7.4463547 | E10: 3000000 | F10: 40000000 | G10: 3500000 | H10: fair | I10: strong | J10: Strong | K10: =_xlfn.XLOOKUP('Main Data'!A10,'PIVOT TABLES'!$A$4:$A$24,'PIVOT TABLES'!$B$4:$B$24,"N/A") -> 3.5 | L10: =_xlfn.XLOOKUP(A10,'PIVOT TABLES'!$D$4:$D$24,'PIVOT TABLES'!$E$4:$E$24,"n/a") -> 4 | M10: 16-18 | N10: keke, Taxi | O10: Cheap | P10: =_xlfn.XLOOKUP(A10,'PIVOT TABLES'!$G$4:$G$24,'PIVOT TABLES'!$H$4:$H$24,"N/A") -> 4 | Q10: Fair | R10: =_xlfn.XLOOKUP(A10,'PIVOT TABLES'!$A$27:$A$47,'PIVOT TABLES'!$B$27:$B$47,"N/A") -> 1.5 | S10: =_xlfn.XLOOKUP(A10,'PIVOT TABLES'!$D$27:$D$47,'PIVOT TABLES'!$E$27:$E$47,"N/A") -> 5 | T10: Cheap
A11: Guzape | B11: Abuja Municipal Area Council (AMAC) | C11: 8.9953852 | D11: 7.5268039 | E11: 4000000 | F11: 60000000 | G11: 4000000 | H11: fair | I11: strong | J11: Strong | K11: =_xlfn.XLOOKUP('Main Data'!A11,'PIVOT TABLES'!$A$4:$A$24,'PIVOT TABLES'!$B$4:$B$24,"N/A") -> 4 | L11: =_xlfn.XLOOKUP(A11,'PIVOT TABLES'!$D$4:$D$24,'PIVOT TABLES'!$E$4:$E$24,"n/a") -> 4 | M11: 18-20 | N11: keke, Taxi | O11: Cheap | P11: =_xlfn.XLOOKUP(A11,'PIVOT TABLES'!$G$4:$G$24,'PIVOT TABLES'!$H$4:$H$24,"N/A") -> 3 | Q11: Fair | R11: =_xlfn.XLOOKUP(A11,'PIVOT TABLES'!$A$27:$A$47,'PIVOT TABLES'!$B$27:$B$47,"N/A") -> 4 | S11: =_xlfn.XLOOKUP(A11,'PIVOT TABLES'!$D$27:$D$47,'PIVOT TABLES'!$E$27:$E$47,"N/A") -> 4 | T11: Fair
A12: Gwarimpa | B12: Abuja Municipal Area Council (AMAC) | C12: 9.1099 | D12: 7.4042 | E12: 1000000 | F12: 8000000 | G12: 2550000 | H12: fair | I12: strong | J12: Strong | K12: =_xlfn.XLOOKUP('Main Data'!A12,'PIVOT TABLES'!$A$4:$A$24,'PIVOT TABLES'!$B$4:$B$24,"N/A") -> 4.3333333 | L12: =_xlfn.XLOOKUP(A12,'PIVOT TABLES'!$D$4:$D$24,'PIVOT TABLES'!$E$4:$E$24,"n/a") -> 3.3333333 | M12: 18-20 | N12: keke, Taxi | O12: Moderate | P12: =_xlfn.XLOOKUP(A12,'PIVOT TABLES'!$G$4:$G$24,'PIVOT TABLES'!$H$4:$H$24,"N/A") -> 3.3333333 | Q12: Fair | R12: =_xlfn.XLOOKUP(A12,'PIVOT TABLES'!$A$27:$A$47,'PIVOT TABLES'!$B$27:$B$47,"N/A") -> 3.6666667 | S12: =_xlfn.XLOOKUP(A12,'PIVOT TABLES'!$D$27:$D$47,'PIVOT TABLES'!$E$27:$E$47,"N/A") -> 4 | T12: Expensive
A13: Zuba | B13: Gwagwalada Area Council (GAC) | C13: 9.1023 | D13: 7.1952 | E13: 250000 | F13: 1000000 | G13: 500000 | H13: slow | I13: slow | J13: fair | K13: =_xlfn.XLOOKUP('Main Data'!A13,'PIVOT TABLES'!$A$4:$A$24,'PIVOT TABLES'!$B$4:$B$24,"N/A") -> 3 | L13: =_xlfn.XLOOKUP(A13,'PIVOT TABLES'!$D$4:$D$24,'PIVOT TABLES'!$E$4:$E$24,"n/a") -> 3 | M13: 6-10 | N13: keke, Taxi, Bus, Bike | O13: Moderate | P13: =_xlfn.XLOOKUP(A13,'PIVOT TABLES'!$G$4:$G$24,'PIVOT TABLES'!$H$4:$H$24,"N/A") -> 2 | Q13: Fair | R13: =_xlfn.XLOOKUP(A13,'PIVOT TABLES'!$A$27:$A$47,'PIVOT TABLES'!$B$27:$B$47,"N/A") -> 1 | S13: =_xlfn.XLOOKUP(A13,'PIVOT TABLES'!$D$27:$D$47,'PIVOT TABLES'!$E$27:$E$47,"N/A") -> 1 | T13: Fair
... A22: Lokogoma | B22: Abuja Municipal Area Council (AMAC) | C22: 8.9786 | D22: 7.4582 | E22: 140000 | F22: 6000000 | G22: 1300000 | H22: fair | I22: fair | J22: strong | K22: =_xlfn.XLOOKUP('Main Data'!A22,'PIVOT TABLES'!$A$4:$A$24,'PIVOT TABLES'!$B$4:$B$24,"N/A") -> 4 | L22: =_xlfn.XLOOKUP(A22,'PIVOT TABLES'!$D$4:$D$24,'PIVOT TABLES'!$E$4:$E$24,"n/a") -> 3.5 | M22: 12-15 | N22: keke, Taxi, Bike | O22: Moderate | P22: =_xlfn.XLOOKUP(A22,'PIVOT TABLES'!$G$4:$G$24,'PIVOT TABLES'!$H$4:$H$24,"N/A") -> 2.5 | Q22: Fair | R22: =_xlfn.XLOOKUP(A22,'PIVOT TABLES'!$A$27:$A$47,'PIVOT TABLES'!$B$27:$B$47,"N/A") -> 3 | S22: =_xlfn.XLOOKUP(A22,'PIVOT TABLES'!$D$27:$D$47,'PIVOT TABLES'!$E$27:$E$47,"N/A") -> 4 | T22: Moderate

Sheet Clean Data
A1: Where do you stay? | B1: Rate your safety status | C1: What’s the overall road quality in your area? | D1: How costly are the goods in your markets in comparison to normal prices? | E1: Which of the transports? | F1: How would you rate your access to healthcare facilities (hospitals , pharmacies , etc)? | G1: What would you rate the quality of said health care services? | H1: What would you rate the availability of recreational areas (parks , sport complexes , tourist attractions , fun zones ,etc)? | I1: What would you rate the availability of supermarket and stores? | J1: How costly would you say said supermarkets and stores are in relativeness to the average services?
A2: Asokoro | B2: 5 | C2: 5 | D2: Expensive | E2: keke, Taxi, Bus | F2: 5 | G2: excellent | H2: 5 | I2: 5 | J2: fair
A3: Asokoro | B3: 4 | C3: 5 | D3: Expensive | E3: Taxi | F3: 3 | G3: fair | H3: 4 | I3: 3 | J3: expensive
A4: Asokoro | B4: 5 | C4: 5 | D4: Moderate | E4: Taxi | F4: 5 | G4: excellent | H4: 2 | I4: 2 | J4: fair
A5: Asokoro | B5: 5 | C5: 5 | D5: Moderate | E5: Taxi | F5: 5 | G5: excellent | H5: 2 | I5: 2 | J5: fair
A6: Asokoro | B6: 4 | C6: 5 | D6: Expensive | E6: keke ,Taxi | F6: 4 | G6: fair | H6: 2 | I6: 4 | J6: fair
A7: Dawaki | B7: 3 | C7: 2 | D7: Expensive | E7: Taxi, Bike(okada) | F7: 4 | G7: fair | H7: 3 | I7: 4 | J7: fair
A8: Dawaki | B8: 4 | C8: 3 | D8: Moderate | E8: Bike(okada) | F8: 3 | G8: fair | H8: 2 | I8: 3 | J8: fair
A9: Dawaki | B9: 4 | C9: 3 | D9: Moderate | E9: keke, Taxi, Bike(okada) | F9: 3 | G9: fair | H9: 3 | I9: 3 | J9: fair
A10: Dawaki | B10: 4 | C10: 2 | D10: Moderate | E10: keke ,Taxi ,Bike(okada) | F10: 3 | G10: fair | H10: 2 | I10: 2 | J10: expensive
A11: Durumi | B11: 3 | C11: 1 | D11: Moderate | E11: keke, Taxi, Bike(okada) | F11: 3 | G11: poor | H11: 2 | I11: 4 | J11: fair
A12: Garki | B12: 4 | C12: 4 | D12: Expensive | E12: Taxi | F12: 5 | G12: fair | H12: 4 | I12: 5 | J12: fair
A13: Guzape | B13: 4 | C13: 4 | D13: Cheap | E13: keke ,Taxi | F13: 3 | G13: fair | H13: 4 | I13: 4 | J13: fair
... A35: Lifecamp | B35: 3 | C35: 3 | D35: Moderate | E35: keke, Bike(okada) | F35: 5 | G35: excellent | H35: 1 | I35: 3 | J35: expensive
A36: Lifecamp | B36: 4 | D36: Moderate | E36: keke, Taxi, Bike(okada) | F36: 4 | G36: fair | H36: 2 | I36: 4 | J36: fair
A37: Lifecamp | B37: 4 | C37: 4 | D37: Moderate | E37: Taxi | F37: 3 | G37: fair | H37: 2 | I37: 4 | J37: fair
A38: Lifecamp | B38: 5 | C38: 5 | D38: Moderate | E38: Taxi | F38: 1 | G38: fair | H38: 3 | I38: 2 | J38: fair
A39: Lokogoma | B39: 4 | C39: 3 | D39: Moderate | E39: keke ,Taxi ,Bike(okada) | F39: 3 | G39: fair | H39: 2 | I39: 4 | J39: Moderate
A40: Lokogoma | B40: 4 | C40: 4 | D40: Moderate | E40: keke ,Taxi ,Bike(okada) | F40: 2 | G40: fair | H40: 4 | I40: 4 | J40: Moderate
A41: Lugbe | B41: 4 | C41: 2 | D41: Moderate | E41: keke, Taxi, Bus, Bike(okada) | F41: 4 | G41: fair | H41: 1 | I41: 4 | J41: fair
A42: Lugbe | B42: 2 | C42: 1 | D42: Moderate | E42: Bike(okada) | F42: 2 | G42: fair | H42: 1 | I42: 2 | J42: expensive
A43: Lugbe | B43: 4 | C43: 4 | D43: Moderate | E43: Taxi | F43: 3 | G43: fair | H43: 2 | I43: 2 | J43: fair
A44: Lugbe | B44: 3 | C44: 3 | D44: Cheap | E44: Taxi | F44: 4 | G44: excellent | H44: 2 | I44: 5 | J44: fair
A45: Maitama | B45: 4 | C45: 4 | D45: Cheap | E45: Taxi | F45: 2 | G45: fair | H45: 4 | I45: 4 | J45: fair
A46: Mararaba | B46: 2 | C46: 3 | D46: Cheap | E46: keke ,Taxi ,Bus ,Bike(okada) | F46: 2 | G46: poor | H46: 1 | I46: 1 | J46: fair
A47: Mpape | B47: 3 | C47: 2 | D47: Moderate | E47: Bus | F47: 4 | G47: fair | H47: 1 | I47: 3 | J47: fair
A48: NYANYA | B48: 3 | C48: 2 | D48: CHEAP | E48: keke ,Taxi ,Bus ,Bike(okada) | F48: 2 | G48: POOR | H48: 2 | I48: 5 | J48: CHEAP
... A57: Zuba | B57: 3 | C57: 3 | D57: Moderate | E57: keke, Taxi, Bus, Bike(okada) | F57: 2 | G57: fair | H57: 1 | I57: 1 | J57: fair

Sheet PIVOT TABLES
A3: Where do you stay? | B3: Average of Rate your safety status | D3: Where do you stay? | E3: Average of What’s the overall road quality in your area? | G3: Where do you stay? | H3: Average of How would you rate your access to healthcare facilities (hospitals , pharmacies , etc)?
A4: Asokoro | B4: 4.6 | D4: Asokoro | E4: 5 | G4: Asokoro | H4: 4.4
A5: Dawaki | B5: 3.75 | D5: Dawaki | E5: 2.5 | G5: Dawaki | H5: 3.25
A6: Durumi | B6: 3 | D6: Durumi | E6: 1 | G6: Durumi | H6: 3
A7: Garki | B7: 4 | D7: Garki | E7: 4 | G7: Garki | H7: 5
A8: Guzape | B8: 4 | D8: Guzape | E8: 4 | G8: Guzape | H8: 3
A9: Gwarimpa | B9: 4.3333333 | D9: Gwarimpa | E9: 3.3333333 | G9: Gwarimpa | H9: 3.3333333
A10: JABI | B10: 5 | D10: JABI | E10: 5 | G10: JABI | H10: 2
A11: Jikwoyi | B11: 3.1666667 | D11: Jikwoyi | E11: 3 | G11: Jikwoyi | H11: 2.6666667
A12: kado | B12: 4.5 | D12: kado | E12: 5 | G12: kado | H12: 3.5
A13: kubwa | B13: 3.8333333 | D13: kubwa | E13: 3 | G13: kubwa | H13: 3.5
A14: Lifecamp | B14: 3.8333333 | D14: Lifecamp | E14: 3.8 | G14: Lifecamp | H14: 3.3333333
A15: Lokogoma | B15: 4 | D15: Lokogoma | E15: 3.5 | G15: Lokogoma | H15: 2.5
... A24: Zuba | B24: 3 | D24: Zuba | E24: 3 | G24: Zuba | H24: 2
A26: Where do you stay? | B26: Average of What would you rate the availability of recreational areas (parks , sport complexes , tourist attractions , fun zones ,etc)? | D26: Where do you stay? | E26: Average of What would you rate the availability of supermarket and stores?
A27: Asokoro | B27: 3 | D27: Asokoro | E27: 3.2
A28: Dawaki | B28: 2.5 | D28: Dawaki | E28: 3
A29: Durumi | B29: 2 | D29: Durumi | E29: 4
A30: Garki | B30: 4 | D30: Garki | E30: 5
A31: Guzape | B31: 4 | D31: Guzape | E31: 4
A32: Gwarimpa | B32: 3.6666667 | D32: Gwarimpa | E32: 4
A33: JABI | B33: 4.5 | D33: JABI | E33: 3
A34: Jikwoyi | B34: 1.6666667 | D34: Jikwoyi | E34: 3.5
A35: kado | B35: 3 | D35: kado | E35: 4
A36: kubwa | B36: 1.8333333 | D36: kubwa | E36: 3.8333333
A37: Lifecamp | B37: 2 | D37: Lifecamp | E37: 3.3333333
A38: Lokogoma | B38: 3 | D38: Lokogoma | E38: 4
... A47: Zuba | B47: 1 | D47: Zuba | E47: 1

Sheet AI prompt Generated table
A1: Area Name | B1: Transport Availability | C1: Cost of Market Items | D1: Quality of Hospitals | E1: Cost of Supermarket/Stores
A2: Kubwa | B2: keke, Taxi, Bus, Bike | C2: Moderate | D2: Fair | E2: Fair/Expensive
A3: Lugbe | B3: Taxi, Bike, keke | C3: Moderate | D3: Fair | E3: Fair
A4: Kado | B4: keke, Taxi | C4: Expensive | D4: Excellent | E4: Expensive
A5: Durumi | B5: keke, Taxi, Bike | C5: Moderate | D5: Poor | E5: Fair
A6: Garki | B6: Taxi | C6: Expensive | D6: Fair | E6: Fair
A7: Maitama | B7: Taxi | C7: Cheap | D7: Fair | E7: Fair
A8: Wuse | B8: Taxi, keke | C8: Moderate | D8: Excellent | E8: Fair/Expensive
A9: Jabi | B9: keke, Taxi | C9: Expensive | D9: Excellent | E9: Moderate
A10: Utako | B10: keke, Taxi | C10: Cheap | D10: Fair | E10: Cheap
A11: Guzape | B11: keke, Taxi | C11: Cheap | D11: Fair | E11: Fair
A12: Gwarimpa | B12: keke, Taxi, Bus, Bike | C12: Moderate | D12: Fair | E12: Expensive
... A22: Lokogoma | B22: keke, Taxi, Bike | C22: Moderate | D22: Fair | E22: Moderate

Sheet Supporting RAW(Data Survey)
A1: start | B1: end | C1: Where do you stay? | D1: Rate your safety status | E1: What’s the overall road quality in your area? | F1: How costly are the goods in your markets in comparison to normal prices? | G1: Which of the transports? | H1: Which of the transports?/keke | I1: Which of the transports?/Taxi | J1: Which of the transports?/Bus | K1: Which of the transports?/Bike(okada) | L1: How would you rate your access to healthcare facilities (hospitals , pharmacies , etc)? | M1: What would you rate the quality of said health care services? | N1: What would you rate the availability of recreational areas (parks , sport complexes , tourist attractions , fun zones ,etc)? | O1: What would you rate the availability of supermarket and stores? | P1: How costly would you say said supermarkets and stores are in relativeness to the average services? | Q1: Where do u stay | R1: what’s the overall road quality in your area | S1: how good is your road network | T1: how costly are the goods in your markets in comparison to normal prices | U1: which of the transports | V1: which of the transports/keke | W1: which of the transports/Taxi | X1: which of the transports/Bus | Y1: which of the transports/Bike(okada) | Z1: how would u rate your access to healthcare facilities (hospitals , pharmacies , etc) | AA1: what would u say the quality of said health care services are | AB1: what would u rate the availability of recreational areas (parks , sport complexes , tourist attractions , fun zones ,etc) | AC1: what you rate the availability of supermarket and stores | AD1: how costly would u say said businesses are in relativeness to the average services | AE1: _id | AF1: _uuid | AG1: _submission_time | AH1: _validation_status | AI1: _notes | AJ1: _status | AK1: _submitted_by | AL1: __version__ | AM1: _tags | AN1: _index
A2: 46050.647 | B2: 46050.647 | D2: 5 | Q2: Asokoro | S2: 5 | AE2: 658104551 | AF2: 6f64e142-7da1-419d-9b16-03be77703aa8 | AG2: 46050.606 | AJ2: submitted_via_web | AL2: vDn9WA6YZmhgw8gvFBNQ9P | AN2: 1
A3: 46050.647 | B3: 46050.647 | D3: 3 | Q3: Gwarimpa | S3: 3 | AE3: 658104854 | AF3: d421ebc5-875e-4254-b194-f2036263d9b9 | AG3: 46050.606 | AJ3: submitted_via_web | AL3: vDn9WA6YZmhgw8gvFBNQ9P | AN3: 2
A4: 46050.647 | B4: 46050.648 | D4: 2 | Q4: Kubwa | S4: 2 | AE4: 658105431 | AF4: 479ffb20-9229-433c-b3aa-71aa93333045 | AG4: 46050.606 | AJ4: submitted_via_web | AL4: vDn9WA6YZmhgw8gvFBNQ9P | AN4: 3
A5: 46050.648 | B5: 46050.648 | D5: 4 | Q5: Lugbe | S5: 3 | AE5: 658105700 | AF5: 2b53281f-519c-461d-9fdd-fc45ad2f4b41 | AG5: 46050.606 | AJ5: submitted_via_web | AL5: vDn9WA6YZmhgw8gvFBNQ9P | AN5: 4
A6: 46050.648 | B6: 46050.648 | D6: 1 | Q6: Nyanya | S6: 2 | AE6: 658106004 | AF6: d07871ff-6ed7-4276-919b-9f5f2aeeb9e6 | AG6: 46050.607 | AJ6: submitted_via_web | AL6: vDn9WA6YZmhgw8gvFBNQ9P | AN6: 5
A7: 46057.785 | B7: 46057.803 | D7: 4 | Q7: Wuse | S7: 5 | T7: Moderate | U7: Taxi | V7: 0 | W7: 1 | X7: 0 | Y7: 0 | Z7: 3 | AA7: fair | AB7: 5 | AC7: 5 | AD7: fair | AE7: 663937859 | AF7: b62222c5-662b-4411-9485-4f0342d9d4b6 | AG7: 46057.762 | AJ7: submitted_via_web | AL7: vPJuJF55pcUVKKBc7B46yi | AN7: 6
A8: 46057.785 | B8: 46057.804 | D8: 4 | Q8: Lifecamp | R8: 3 | T8: Moderate | U8: keke Taxi Bike(okada) | V8: 1 | W8: 1 | X8: 0 | Y8: 1 | Z8: 4 | AA8: fair | AB8: 3 | AC8: 3 | AD8: fair | AE8: 663937976 | AF8: 0b3ec5e1-05b8-4435-9ec1-ab472a4f294f | AG8: 46057.762 | AJ8: submitted_via_web | AL8: vC57xmFuoaBeCFipfYzy3x | AN8: 7
A9: 46057.801 | B9: 46057.804 | D9: 3 | Q9: Lifecamp | S9: 4 | T9: Expensive | U9: keke Taxi Bike(okada) | V9: 1 | W9: 1 | X9: 0 | Y9: 1 | Z9: 3 | AA9: fair | AB9: 1 | AC9: 4 | AD9: fair | AE9: 663938015 | AF9: 452a90b2-cbe9-498e-87af-6802312a4802 | AG9: 46057.762 | AJ9: submitted_via_web | AL9: vPJuJF55pcUVKKBc7B46yi | AN9: 8
A10: 46057.807 | B10: 46057.811 | D10: 5 | Q10: Asokoro | R10: 5 | T10: Expensive | U10: keke Taxi Bus | V10: 1 | W10: 1 | X10: 1 | Y10: 0 | Z10: 5 | AA10: excellent | AB10: 5 | AC10: 5 | AD10: fair | AE10: 663943066 | AF10: ba3f4c14-8eff-42b8-a12f-d47e3f08e1be | AG10: 46057.769 | AJ10: submitted_via_web | AL10: vC57xmFuoaBeCFipfYzy3x | AN10: 9
A11: 46057.896 | B11: 46057.897 | C11: Asokoro | D11: 4 | E11: 5 | F11: Expensive | G11: Taxi | H11: 0 | I11: 1 | J11: 0 | K11: 0 | L11: 3 | M11: fair | N11: 4 | O11: 3 | P11: expensive | AE11: 663989485 | AF11: 3d995408-fd83-4342-bf07-58f8acba544f | AG11: 46057.855 | AJ11: submitted_via_web | AL11: vGpHDy2HuGtMjGP87gmJYG | AN11: 10
A12: 46057.897 | B12: 46057.897 | AE12: 663989609 | AF12: f1fd7de7-95a1-44bd-a535-05aa35e35307 | AG12: 46057.855 | AJ12: submitted_via_web | AL12: vGpHDy2HuGtMjGP87gmJYG | AN12: 11
A13: 46057.897 | B13: 46057.898 | C13: Gwarimpa | D13: 5 | E13: 5 | F13: Expensive | G13: keke Taxi Bus Bike(okada) | H13: 1 | I13: 1 | J13: 1 | K13: 1 | L13: 4 | M13: fair | N13: 4 | O13: 5 | P13: expensive | AE13: 663989992 | AF13: 0c1e903a-c4ac-4a25-a2f8-d94d1e413139 | AG13: 46057.856 | AJ13: submitted_via_web | AL13: vGpHDy2HuGtMjGP87gmJYG | AN13: 12
A14: 46057.896 | B14: 46057.898 | C14: Mpape | D14: 3 | E14: 2 | F14: Moderate | G14: Bus | H14: 0 | I14: 0 | J14: 1 | K14: 0 | L14: 4 | M14: fair | N14: 1 | O14: 3 | P14: fair | AE14: 663990166 | AF14: bc28ddcf-87f7-4de0-a126-41c31d7825f9 | AG14: 46057.857 | AJ14: submitted_via_web | AL14: vGpHDy2HuGtMjGP87gmJYG | AN14: 13
A15: 46057.902 | B15: 46057.903 | C15: kubwa | D15: 4 | E15: 3 | F15: Moderate | G15: keke Taxi Bus Bike(okada) | H15: 1 | I15: 1 | J15: 1 | K15: 1 | L15: 3 | M15: fair | N15: 3 | O15: 3 | P15: fair | AE15: 663992379 | AF15: b0581ea7-50e6-48e9-9854-de9b5701131b | AG15: 46057.862 | AJ15: submitted_via_web | AL15: vGpHDy2HuGtMjGP87gmJYG | AN15: 14
A16: 46057.905 | B16: 46057.906 | C16: Durumi | D16: 3 | E16: 1 | F16: Moderate | G16: keke Taxi Bike(okada) | H16: 1 | I16: 1 | J16: 0 | K16: 1 | L16: 3 | M16: poor | N16: 2 | O16: 4 | P16: fair | AE16: 663993753 | AF16: 7158c0c1-0f17-4529-9ba1-59a5d2ebbe8a | AG16: 46057.864 | AJ16: submitted_via_web | AL16: vGpHDy2HuGtMjGP87gmJYG | AN16: 15
A17: 46057.91 | B17: 46057.91 | AE17: 663995560 | AF17: 148e7b13-6980-4198-9eff-48059232af69 | AG17: 46057.869 | AJ17: submitted_via_web | AL17: vGpHDy2HuGtMjGP87gmJYG | AN17: 16
A18: 46057.91 | B18: 46057.911 | C18: kubwa | D18: 3 | E18: 1 | F18: Moderate | G18: keke Taxi Bus Bike(okada) | H18: 1 | I18: 1 | J18: 1 | K18: 1 | L18: 2 | M18: fair | N18: 1 | O18: 3 | P18: expensive | AE18: 663995779 | AF18: 476f4add-67d6-44fa-a112-26bce9ace5d3 | AG18: 46057.87 | AJ18: submitted_via_web | AL18: vGpHDy2HuGtMjGP87gmJYG | AN18: 17
A19: 46057.91 | B19: 46057.911 | C19: Jikwoyi | D19: 4 | E19: 4 | F19: Moderate | G19: keke Taxi Bus Bike(okada) | H19: 1 | I19: 1 | J19: 1 | K19: 1 | L19: 2 | M19: poor | N19: 2 | O19: 4 | P19: fair | AE19: 663995857 | AF19: 829d87b6-d8da-4cbe-a036-8cbad492d7bc | AG19: 46057.87 | AJ19: submitted_via_web | AL19: vGpHDy2HuGtMjGP87gmJYG | AN19: 18
A20: 46057.941 | B20: 46057.942 | C20: Lugbe | D20: 4 | E20: 2 | F20: Moderate | G20: keke Taxi Bus Bike(okada) | H20: 1 | I20: 1 | J20: 1 | K20: 1 | L20: 4 | M20: fair | N20: 1 | O20: 4 | P20: fair | AE20: 664007234 | AF20: 12ae0824-ab78-482c-bdbb-bfc3ffd66c1e | AG20: 46057.9 | AJ20: submitted_via_web | AL20: vGpHDy2HuGtMjGP87gmJYG | AN20: 19
A21: 46057.976 | B21: 46057.977 | C21: kubwa | D21: 5 | E21: 4 | F21: Moderate | G21: keke Taxi Bike(okada) | H21: 1 | I21: 1 | J21: 0 | K21: 1 | L21: 4 | M21: fair | N21: 2 | O21: 5 | P21: fair | AE21: 664018771 | AF21: 73d1eabf-84ce-489b-a198-a1ba473e98fb | AG21: 46057.935 | AJ21: submitted_via_web | AL21: vGpHDy2HuGtMjGP87gmJYG | AN21: 20
A22: 46057.991 | B22: 46057.992 | C22: Zuba | D22: 3 | E22: 3 | F22: Moderate | G22: keke Taxi Bus Bike(okada) | H22: 1 | I22: 1 | J22: 1 | K22: 1 | L22: 2 | M22: fair | N22: 1 | O22: 1 | P22: fair | AE22: 664024266 | AF22: 3e89c0e4-bb07-4fb9-a2d7-b91b5f5e95f2 | AG22: 46057.951 | AJ22: submitted_via_web | AL22: vGpHDy2HuGtMjGP87gmJYG | AN22: 21
A23: 46058.008 | B23: 46058.009 | C23: Lifecamp | D23: 3 | E23: 3 | F23: Moderate | G23: keke Bike(okada) | H23: 1 | I23: 0 | J23: 0 | K23: 1 | L23: 5 | M23: excellent | N23: 1 | O23: 3 | P23: expensive | AE23: 664030716 | AF23: 9dfff8a4-4989-4847-b3c1-8bd85f9ab40b | AG23: 46057.967 | AJ23: submitted_via_web | AL23: vGpHDy2HuGtMjGP87gmJYG | AN23: 22
A24: 46058.153 | B24: 46058.154 | C24: Lifecamp | D24: 5 | E24: 5 | F24: Moderate | L24: 3 | M24: fair | N24: 3 | O24: 5 | P24: fair | AE24: 664082217 | AF24: 9d0ddcdc-ec3c-49c8-ae51-96f83f6dbb6e | AG24: 46058.112 | AJ24: submitted_via_web | AL24: vGpHDy2HuGtMjGP87gmJYG | AN24: 23
A25: 46058.175 | B25: 46058.175 | AE25: 664091152 | AF25: d6870370-8fde-402d-a948-430744250cd6 | AG25: 46058.134 | AJ25: submitted_via_web | AL25: vGpHDy2HuGtMjGP87gmJYG | AN25: 24
A26: 46058.227 | B26: 46058.228 | C26: Dawaki | D26: 3 | E26: 2 | F26: Expensive | G26: Taxi Bike(okada) | H26: 0 | I26: 1 | J26: 0 | K26: 1 | L26: 4 | M26: fair | N26: 3 | O26: 4 | P26: fair | AE26: 664111109 | AF26: 411ab96c-d12a-47bb-a239-c1e61b5aaea7 | AG26: 46058.186 | AJ26: submitted_via_web | AL26: vGpHDy2HuGtMjGP87gmJYG | AN26: 25
A27: 46058.287 | B27: 46058.288 | D27: 4 | Q27: Lifecamp | R27: 3 | T27: Moderate | U27: keke Taxi Bike(okada) | V27: 1 | W27: 1 | X27: 0 | Y27: 1 | Z27: 4 | AA27: fair | AB27: 2 | AC27: 4 | AD27: fair | AE27: 664159774 | AF27: 9236a538-802d-47f5-9d26-9f3fa7f64e34 | AG27: 46058.247 | AJ27: submitted_via_web | AL27: vNGFHn2gqY9JTYp93WsixP | AN27: 26
A28: 46058.313 | B28: 46058.314 | C28: kubwa | D28: 5 | E28: 4 | F28: Moderate | G28: keke Taxi Bike(okada) | H28: 1 | I28: 1 | J28: 0 | K28: 1 | L28: 5 | M28: fair | N28: 1 | O28: 4 | P28: expensive | AE28: 664188257 | AF28: 7eb63efe-87bd-451b-84b3-3522eb62b5a4 | AG28: 46058.272 | AJ28: submitted_via_web | AL28: vGpHDy2HuGtMjGP87gmJYG | AN28: 27
A29: 46058.325 | B29: 46058.327 | C29: Lifecamp | D29: 4 | E29: 4 | F29: Moderate | G29: Taxi | H29: 0 | I29: 1 | J29: 0 | K29: 0 | L29: 3 | M29: fair | N29: 2 | O29: 4 | P29: fair | AE29: 664205042 | AF29: 6e0cb68d-7f92-4009-9299-e66f31d282e8 | AG29: 46058.285 | AJ29: submitted_via_web | AL29: vsGKeWeTni5oq8Le5ZTJ9x | AN29: 28
A30: 46058.405 | B30: 46058.406 | C30: Lugbe | D30: 2 | E30: 1 | F30: Moderate | G30: Bike(okada) | H30: 0 | I30: 0 | J30: 0 | K30: 1 | L30: 2 | M30: fair | N30: 1 | O30: 2 | P30: expensive | AE30: 664314078 | AF30: bf73efbd-42a1-4380-968a-21653d6b9bd2 | AG30: 46058.365 | AJ30: submitted_via_web | AL30: vsGKeWeTni5oq8Le5ZTJ9x | AN30: 29
A31: 46058.446 | B31: 46058.453 | C31: Dawaki | D31: 4 | E31: 3 | F31: Moderate | G31: Bike(okada) | H31: 0 | I31: 0 | J31: 0 | K31: 1 | L31: 3 | M31: fair | N31: 2 | O31: 3 | P31: fair | AE31: 664388813 | AF31: 2e538900-6d1e-48c1-8d91-3d1e94feb316 | AG31: 46058.412 | AJ31: submitted_via_web | AL31: vsGKeWeTni5oq8Le5ZTJ9x | AN31: 30
A32: 46058.453 | B32: 46058.458 | C32: Dawaki | D32: 4 | E32: 3 | F32: Moderate | G32: keke Taxi Bike(okada) | H32: 1 | I32: 1 | J32: 0 | K32: 1 | L32: 3 | M32: fair | N32: 3 | O32: 3 | P32: fair | AE32: 664396740 | AF32: 9395e55f-d97c-457b-8502-39f4366cc8bf | AG32: 46058.416 | AJ32: submitted_via_web | AL32: vsGKeWeTni5oq8Le5ZTJ9x | AN32: 31
A33: 46058.546 | B33: 46058.547 | C33: Jikwoyi | D33: 4 | E33: 3 | F33: Moderate | G33: keke Bus Bike(okada) | H33: 1 | I33: 0 | J33: 1 | K33: 1 | L33: 4 | M33: fair | N33: 1 | O33: 3 | P33: fair | AE33: 664527669 | AF33: 7d89ee91-c64e-422f-be95-a82e89b9ba1a | AG33: 46058.506 | AJ33: submitted_via_web | AL33: vsGKeWeTni5oq8Le5ZTJ9x | AN33: 32
A34: 46058.589 | B34: 46058.59 | C34: Jikwoyi | D34: 3 | E34: 3 | F34: Moderate | G34: keke Bike(okada) | H34: 1 | I34: 0 | J34: 0 | K34: 1 | L34: 2 | M34: poor | N34: 1 | O34: 2 | P34: expensive | AE34: 664581494 | AF34: 2b803203-5a43-4516-86d5-5bba51305d67 | AG34: 46058.549 | AJ34: submitted_via_web | AL34: vsGKeWeTni5oq8Le5ZTJ9x | AN34: 33
A35: 46058.608 | B35: 46058.609 | C35: Asokoro | D35: 5 | E35: 5 | F35: Moderate | G35: Taxi | H35: 0 | I35: 1 | J35: 0 | K35: 0 | L35: 5 | M35: excellent | N35: 2 | O35: 2 | P35: fair | AE35: 664605813 | AF35: b186022f-dd68-41fb-afd6-9593b5005c82 | AG35: 46058.567 | AJ35: submitted_via_web | AL35: vsGKeWeTni5oq8Le5ZTJ9x | AN35: 34
A36: 46059.472 | B36: 46059.474 | C36: Guzape | D36: 4 | E36: 4 | F36: Cheap | L36: 3 | M36: fair | N36: 4 | O36: 4 | P36: fair | AE36: 665255460 | AF36: 72f3b360-a6a9-4ae6-90b5-326a8a36779b | AG36: 46059.432 | AJ36: submitted_via_web | AL36: vsGKeWeTni5oq8Le5ZTJ9x | AN36: 35
A37: 46059.474 | B37: 46059.475 | C37: kubwa | D37: 3 | E37: 4 | F37: Moderate | G37: keke | H37: 1 | I37: 0 | J37: 0 | K37: 0 | L37: 4 | M37: fair | N37: 3 | O37: 5 | P37: fair | AE37: 665257391 | AF37: 6fb93029-2c66-4d63-879a-339689da8752 | AG37: 46059.434 | AJ37: submitted_via_web | AL37: vsGKeWeTni5oq8Le5ZTJ9x | AN37: 36
A38: 46059.496 | B38: 46059.496 | C38: Wuse | D38: 4 | E38: 4 | F38: Moderate | G38: Taxi | H38: 0 | I38: 1 | J38: 0 | K38: 0 | L38: 4 | M38: excellent | N38: 5 | O38: 5 | P38: expensive | AE38: 665280356 | AF38: e78b8876-18fe-4155-9a53-c885cbcc1dac | AG38: 46059.455 | AJ38: submitted_via_web | AL38: vsGKeWeTni5oq8Le5ZTJ9x | AN38: 37
A39: 46059.503 | B39: 46059.504 | C39: kubwa | D39: 3 | E39: 2 | F39: Expensive | G39: Bus | H39: 0 | I39: 0 | J39: 1 | K39: 0 | L39: 3 | M39: poor | N39: 1 | O39: 3 | P39: expensive | AE39: 665288943 | AF39: 67146d11-2720-40ed-8fbd-f93b3aeaf49f | AG39: 46059.463 | AJ39: submitted_via_web | AL39: vsGKeWeTni5oq8Le5ZTJ9x | AN39: 38
A40: 46059.504 | B40: 46059.505 | C40: Maitama | D40: 4 | E40: 4 | F40: Cheap | G40: Taxi | H40: 0 | I40: 1 | J40: 0 | K40: 0 | L40: 2 | M40: fair | N40: 4 | O40: 4 | P40: fair | AE40: 665289416 | AF40: ab68a658-0b02-4e69-8ff4-a4c90066487b | AG40: 46059.463 | AJ40: submitted_via_web | AL40: vsGKeWeTni5oq8Le5ZTJ9x | AN40: 39
...
